2024-09-15 09:50:38,487 - INFO - Starting configuration setup
2024-09-15 09:50:38,487 - INFO - Environment variables loaded successfully
2024-09-15 09:50:38,488 - INFO - Twitter API client initialized successfully
2024-09-15 09:50:40,527 - INFO - Initializing text-generation model: EleutherAI/gpt-neo-1.3B
2024-09-15 09:51:03,521 - INFO - Model initialized successfully
2024-09-15 09:51:03,521 - INFO - Starting tweet scheduling
2024-09-15 09:51:03,521 - INFO - Tweeting process started at 2024-09-15 09:51:03.521948!
2024-09-15 09:51:03,522 - CRITICAL - Unhandled exception in main application
Traceback (most recent call last):
  File "/home/runner/work/TechInsightX/TechInsightX/src/main.py", line 11, in <module>
    tweet_ai_news()
  File "/home/runner/work/TechInsightX/TechInsightX/src/scheduler.py", line 48, in tweet_ai_news
    load_posted_urls()
  File "/home/runner/work/TechInsightX/TechInsightX/src/scheduler.py", line 30, in load_posted_urls
    posted_urls[row["Link"]] = row["DateTime"]
                               ~~~^^^^^^^^^^^^
KeyError: 'DateTime'
